{
 "cells": [
  {
   "cell_type": "code",
   "execution_count": null,
   "id": "75217324-4d6d-4c5d-a934-297e02812f3b",
   "metadata": {},
   "outputs": [],
   "source": [
    "#Q1.\n",
    "\"\"\"In Python, an exception is an event that interrupts the normal flow of a program's execution.\n",
    "When an exception occurs, the program stops running and Python displays an error message indicating the type of exception\n",
    "that was raised and where in the code it occurred.\n",
    "\n",
    "Now, regarding the difference between exceptions and syntax errors in Python:\n",
    "\n",
    "1.Exceptions are raised during the execution of a program, while syntax errors are detected by the Python interpreter\n",
    "before the program is executed.\n",
    "2.Exceptions are caused by errors or unexpected events that occur during the execution of a program,\n",
    "while syntax errors are caused by incorrect Python syntax or grammar that makes it impossible for the interpreter\n",
    "to understand the program.\n",
    "3.Exceptions can be caught and handled by the program using try-except blocks, while syntax errors must be fixed before\n",
    "the program can be executed\"\"\""
   ]
  },
  {
   "cell_type": "code",
   "execution_count": null,
   "id": "3c146315-622c-486e-adae-3c9c00ec6752",
   "metadata": {},
   "outputs": [],
   "source": [
    "#Q2.\n",
    "\"\"\"When an exception is not handled in Python, it causes the program to terminate abruptly and display an error\n",
    "message indicating the type of exception that was raised and where in the code it occurred. This can be problematic\n",
    "if the program needs to continue running, or if there are critical resources that need to be released properly.\n",
    "\n",
    "Here's an example of what happens when an exception is not handled:\n",
    "try:\n",
    "    x = 1/0 \n",
    "except ValueError:\n",
    "    print(\"Oops! Something went wrong.\")\n",
    "    \n",
    "In this example, the code inside the try block attempts to divide the number 1 by 0, which is an invalid operation and will\n",
    "raise a ZeroDivisionError exception. However, there is no except block that handles this type of exception, so the program\n",
    "will terminate with an error message that looks something like this:\n",
    "\n",
    "\"ZeroDivisionError: division by zero\"\n",
    "\"\"\""
   ]
  },
  {
   "cell_type": "code",
   "execution_count": null,
   "id": "6fc1c60b-ce89-426c-ba8a-93c073d2356c",
   "metadata": {},
   "outputs": [],
   "source": [
    "#Q3.\n",
    "\"\"\"In Python, try-except statements are used to catch and handle exceptions that occur during program execution.\n",
    "\n",
    "The try block contains the code that might raise an exception, and the except block is where you define how to handle\n",
    "the exception. Here is an example:\n",
    "\n",
    "\n",
    "try:\n",
    "    x = int(input(\"Please enter a number: \"))\n",
    "    y = 10 / x\n",
    "    print(\"y = \", y)\n",
    "except ZeroDivisionError:\n",
    "    print(\"Error: Cannot divide by zero.\")\n",
    "except ValueError:\n",
    "    print(\"Error: Please enter a valid number.\")\n",
    "\n",
    "\n",
    "In this example, the try block prompts the user to input a number and then tries to divide 10 by that number.\n",
    "If the user inputs zero, a ZeroDivisionError will occur, and the program will jump to the corresponding except block\n",
    "and print an error message. If the user inputs a non-numeric value, a ValueError will occur, and the program will jump\n",
    "to the other except block and print a different error message.\n",
    "Using try-except statements is a good practice for handling errors and preventing your program from crashing unexpectedly.\"\"\""
   ]
  },
  {
   "cell_type": "code",
   "execution_count": null,
   "id": "dae1574e-4c0b-4837-a40a-948563cd2d8d",
   "metadata": {},
   "outputs": [],
   "source": [
    "#Q4.\n",
    "\"\"\"\n",
    "a. try and else:\n",
    "In Python, you can also use the else block with the try block to run some code when no exception occurs. Here is an example:\n",
    "\n",
    "try:\n",
    "    x = int(input(\"Please enter a number: \"))\n",
    "    y = 10 / x\n",
    "except ZeroDivisionError:\n",
    "    print(\"Error: Cannot divide by zero.\")\n",
    "else:\n",
    "    print(\"y = \", y)\n",
    "\n",
    "In this example, if the user inputs zero, the program will jump to the except block and print an error message. \n",
    "Otherwise, the program will execute the else block and print the result of the division.\n",
    "\n",
    "b. finally:\n",
    "The finally block is used to execute some code after the try and except blocks, regardless of whether an exception was\n",
    "raised or not. Here is an example:\n",
    "\n",
    "try:\n",
    "    f = open(\"myfile.txt\")\n",
    "    # some code that might raise an exception\n",
    "except:\n",
    "    print(\"Error: Cannot open file.\")\n",
    "finally:\n",
    "    f.close()\n",
    "\n",
    "In this example, the try block tries to open a file and execute some code that might raise an exception. \n",
    "If an exception occurs, the program will jump to the except block and print an error message. Then, the finally \n",
    "block will execute and close the file.\n",
    "\n",
    "c. raise:\n",
    "The raise statement is used to raise an exception manually. You can use it to signal an error condition\n",
    "that is not automatically detected by Python. Here is an example:\n",
    "\n",
    "def divide(x, y):\n",
    "    if y == 0:\n",
    "        raise ZeroDivisionError(\"Error: Cannot divide by zero.\")\n",
    "    else:\n",
    "        return x / y\n",
    "\n",
    "try:\n",
    "    result = divide(10, 0)\n",
    "except ZeroDivisionError as e:\n",
    "    print(e)\n",
    "\n",
    "\n",
    "In this example, the divide function raises a ZeroDivisionError exception if the second argument is zero. Then, the\n",
    "try block calls the divide function with the arguments 10 and 0, which causes an exception to be raised. Finally, the\n",
    "except block catches the exception and prints an error message.\n",
    "\"\"\""
   ]
  },
  {
   "cell_type": "code",
   "execution_count": null,
   "id": "458363ad-9057-42b4-8320-5af0fde042d2",
   "metadata": {},
   "outputs": [],
   "source": [
    "#Q5.\n",
    "\"\"\"\n",
    "In Python, custom exceptions are user-defined exceptions that extend the base Exception class or its subclasses.\n",
    "You can create custom exceptions to represent specific error conditions that are not covered by the built-in exceptions.\n",
    "We need custom exceptions because they can help to make our code more modular, reusable, and easier to maintain.\n",
    "By defining our own exceptions, we can provide more informative error messages and handle specific errors in a more \n",
    "specialized way.\n",
    "\n",
    "Here is an example of how to create and use a custom exception in Python:\n",
    "\n",
    "class CustomError(Exception):\n",
    "    def __init__(self, message):\n",
    "        self.message = message\n",
    "        \n",
    "    def __str__(self):\n",
    "        return f\"CustomError: {self.message}\"\n",
    "\n",
    "def divide(x, y):\n",
    "    if y == 0:\n",
    "        raise CustomError(\"Cannot divide by zero.\")\n",
    "    else:\n",
    "        return x / y\n",
    "\n",
    "try:\n",
    "    result = divide(10, 0)\n",
    "except CustomError as e:\n",
    "    print(e)\n",
    "\n",
    "\n",
    "In this example, we define a custom exception called CustomError that takes a message as input and inherits from the base\n",
    "Exception class. We also define a function called divide that raises a CustomError exception if the second argument is zero.\n",
    "Then, we use a try-except block to catch the CustomError exception and print the error message.\n",
    "\n",
    "By using a custom exception, we can provide more informative error messages to the user and handle the specific error\n",
    "condition in a more specialized way. This can make our code more modular, reusable, and easier to maintain.\n",
    "\"\"\""
   ]
  },
  {
   "cell_type": "code",
   "execution_count": 1,
   "id": "178c5347-63a6-4ac7-9389-45334d93f172",
   "metadata": {},
   "outputs": [
    {
     "name": "stdout",
     "output_type": "stream",
     "text": [
      "Cannot divide by zero\n"
     ]
    }
   ],
   "source": [
    "#Q6.\n",
    "class CustomException(Exception):\n",
    "    pass\n",
    "\n",
    "def divide(a, b):\n",
    "    if b == 0:\n",
    "        raise CustomException(\"Cannot divide by zero\")\n",
    "    return a / b\n",
    "\n",
    "try:\n",
    "    result = divide(10, 0)\n",
    "except CustomException as e:\n",
    "    print(e)\n"
   ]
  },
  {
   "cell_type": "code",
   "execution_count": null,
   "id": "0e507c73-9700-4e43-99e1-0c1b18e02b0e",
   "metadata": {},
   "outputs": [],
   "source": []
  }
 ],
 "metadata": {
  "kernelspec": {
   "display_name": "Python 3 (ipykernel)",
   "language": "python",
   "name": "python3"
  },
  "language_info": {
   "codemirror_mode": {
    "name": "ipython",
    "version": 3
   },
   "file_extension": ".py",
   "mimetype": "text/x-python",
   "name": "python",
   "nbconvert_exporter": "python",
   "pygments_lexer": "ipython3",
   "version": "3.10.8"
  }
 },
 "nbformat": 4,
 "nbformat_minor": 5
}
